<?xml version="1.0" ?>
<!-- ROS2 Control Hardware Plugin for BrickPi3 -->
<robot name="kitt">
  <link name="base_link"></link>
  <link name="left_wheel"></link>
  <link name="right_wheel"></link>
  <link name="steer_axis"></link>
  <joint name="left_traction_wheel" type="continuous">
    <parent link="base_link"/>
    <child link="left_wheel"/>
  </joint>
  <joint name="right_traction_wheel" type="continuous">
    <parent link="base_link"/>
    <child link="right_wheel"/>
  </joint>
  <joint name="steer_axis" type="continuous">
    <parent link="base_link"/>
    <child link="steer_axis"/>
  </joint>
  <ros2_control name="KittHardware" type="system">
    <hardware>
      <plugin>kitt_hardware/KittHardware</plugin>
      <param name="hw_start_duration_sec">0</param>
      <param name="hw_stop_duration_sec">3.0</param>
    </hardware>
    <joint name="left_traction_wheel">
      <command_interface name="velocity"/>
      <state_interface name="position"/>
      <state_interface name="velocity"/>
    </joint>
    <joint name="right_traction_wheel">
      <command_interface name="velocity"/>
      <state_interface name="position"/>
      <state_interface name="velocity"/>
    </joint>
    <joint name="steer_axis">
      <command_interface name="position"/>
      <state_interface name="position"/>
      <state_interface name="velocity"/>
    </joint>
  </ros2_control>
</robot>
